gdax_sample_01.json
[
{
    "type": "received",
    "time": "2014-11-07T08:19:27.028459Z",
    "product_id": "BTC-USD",
    "sequence": 1,
    "order_id": "d50ec984-77a8-460a-b958-66f114b0de9b",
    "size": "1.34",
    "price": "502.1",
    "side": "buy",
    "order_type": "limit"
},
{
    "type": "received",
    "time": "2014-11-09T08:19:27.028459Z",
    "product_id": "BTC-USD",
    "sequence": 2,
    "order_id": "dddec984-77a8-460a-b958-66f114b0de9b",
    "funds": "3000.234",
    "side": "buy",
    "order_type": "market"
},
{
    "type": "open",
    "time": "2014-11-07T08:19:27.028459Z",
    "product_id": "BTC-USD",
    "sequence": 3,
    "order_id": "d50ec984-77a8-460a-b958-66f114b0de9b",
    "price": "200.2",
    "remaining_size": "1.00",
    "side": "sell"
},
{
    "type": "open",
    "time": "2014-11-07T08:19:27.028459Z",
    "product_id": "BTC-USD",
    "sequence": 4,
    "order_id": "d50ec984-77a8-460a-b958-66f114b0de7c",
    "price": "199.8",
    "remaining_size": "3.00",
    "side": "buy"
},
{
    "type": "open",
    "time": "2014-11-07T08:19:27.028459Z",
    "product_id": "BTC-USD",
    "sequence": 5,
    "order_id": "d50ec984-77a8-460a-b958-66f114b0de6d",
    "price": "200.4",
    "remaining_size": "7.00",
    "side": "sell"
},
{
    "type": "done",
    "time": "2014-11-07T08:19:27.028459Z",
    "product_id": "BTC-USD",
    "sequence": 6,
    "price": "200.2",
    "order_id": "d50ec984-77a8-460a-b958-66f114b0de9b",
    "reason": "filled",
    "side": "sell",
    "remaining_size": "0"
},
{
    "type": "done",
    "time": "2014-11-07T08:19:27.028459Z",
    "product_id": "BTC-USD",
    "sequence": 7,
    "price": "200.2",
    "order_id": "d50ec984-77a8-460a-b958-66f114b0de9c",
    "reason": "filled",
    "side": "sell",
    "remaining_size": "0"
},
{
    "type": "done",
    "time": "2014-11-07T08:19:27.028459Z",
    "product_id": "BTC-USD",
    "sequence": 8,
    "price": "200.9",
    "order_id": "d50ec984-77a8-460a-b958-66f114b0de9b",
    "reason": "filled",
    "side": "sell",
    "remaining_size": "0"
},
{
    "type": "match",
    "trade_id": 10,
    "sequence": 9,
    "maker_order_id": "d50ec984-77a8-460a-b958-66f114b0de6d",
    "taker_order_id": "132fb6ae-456b-4654-b4e0-d681ac05cea1",
    "time": "2014-11-07T08:19:27.028459Z",
    "product_id": "BTC-USD",
    "size": "5.23512",
    "price": "200.4",
    "side": "sell"
},
{
    "type": "match",
    "trade_id": 10,
    "sequence": 10,
    "maker_order_id": "ac928c66-ca53-498f-9c13-a110027a60e8",
    "taker_order_id": "132fb6ae-456b-4654-b4e0-d681ac05cea1",
    "time": "2014-11-07T08:19:27.028459Z",
    "product_id": "BTC-USD",
    "size": "5.23512",
    "price": "400.23",
    "side": "sell"
},
{
    "type": "change",
    "time": "2014-11-07T08:19:27.028459Z",
    "sequence": 11,
    "order_id": "ac928c66-ca53-498f-9c13-a110027a60e8",
    "product_id": "BTC-USD",
    "new_size": "5.23512",
    "old_size": "12.234412",
    "price": "400.23",
    "side": "sell"
},
{
    "type": "open",
    "time": "2014-11-07T08:19:27.028459Z",
    "product_id": "BTC-USD",
    "sequence": 12,
    "order_id": "d50ec984-77a8-460a-b958-66f114b0de9b",
    "price": "143.2",
    "remaining_size": "1.00",
    "side": "sell"
},
{
    "type": "open",
    "time": "2014-11-07T08:19:27.028459Z",
    "product_id": "BTC-USD",
    "sequence": 13,
    "order_id": "d50ec984-77a8-460a-b958-66f114b0de9b",
    "price": "133.2",
    "remaining_size": "1.00",
    "side": "sell"
}
]
